[2024-08-17T18:45:40.881+0000] {taskinstance.py:1956} INFO - Dependencies all met for dep_context=non-requeueable deps ti=<TaskInstance: etl.scale_data manual__2024-08-17T18:40:10.068630+00:00 [queued]>
[2024-08-17T18:45:40.886+0000] {taskinstance.py:1956} INFO - Dependencies all met for dep_context=requeueable deps ti=<TaskInstance: etl.scale_data manual__2024-08-17T18:40:10.068630+00:00 [queued]>
[2024-08-17T18:45:40.886+0000] {taskinstance.py:2170} INFO - Starting attempt 4 of 5
[2024-08-17T18:45:40.894+0000] {taskinstance.py:2191} INFO - Executing <Task(PythonOperator): scale_data> on 2024-08-17 18:40:10.068630+00:00
[2024-08-17T18:45:40.899+0000] {standard_task_runner.py:60} INFO - Started process 3914 to run task
[2024-08-17T18:45:40.900+0000] {standard_task_runner.py:87} INFO - Running: ['***', 'tasks', 'run', 'etl', 'scale_data', 'manual__2024-08-17T18:40:10.068630+00:00', '--job-id', '91', '--raw', '--subdir', 'DAGS_FOLDER/etl_process.py', '--cfg-path', '/tmp/tmppzt0tn3e']
[2024-08-17T18:45:40.902+0000] {standard_task_runner.py:88} INFO - Job 91: Subtask scale_data
[2024-08-17T18:45:40.930+0000] {task_command.py:423} INFO - Running <TaskInstance: etl.scale_data manual__2024-08-17T18:40:10.068630+00:00 [running]> on host 5a9976bc6527
[2024-08-17T18:45:40.979+0000] {taskinstance.py:2480} INFO - Exporting env vars: AIRFLOW_CTX_DAG_OWNER='***' AIRFLOW_CTX_DAG_ID='etl' AIRFLOW_CTX_TASK_ID='scale_data' AIRFLOW_CTX_EXECUTION_DATE='2024-08-17T18:40:10.068630+00:00' AIRFLOW_CTX_TRY_NUMBER='4' AIRFLOW_CTX_DAG_RUN_ID='manual__2024-08-17T18:40:10.068630+00:00'
[2024-08-17T18:45:40.980+0000] {etl_process.py:285} INFO - Leyendo Datos
[2024-08-17T18:45:40.990+0000] {etl_process.py:292} INFO - Datos Leidos
[2024-08-17T18:45:40.996+0000] {logging_mixin.py:188} WARNING - /home/***/.local/lib/python3.8/site-packages/sklearn/utils/extmath.py:1050 RuntimeWarning: invalid value encountered in divide
[2024-08-17T18:45:40.996+0000] {logging_mixin.py:188} WARNING - /home/***/.local/lib/python3.8/site-packages/sklearn/utils/extmath.py:1055 RuntimeWarning: invalid value encountered in divide
[2024-08-17T18:45:40.997+0000] {logging_mixin.py:188} WARNING - /home/***/.local/lib/python3.8/site-packages/sklearn/utils/extmath.py:1075 RuntimeWarning: invalid value encountered in divide
[2024-08-17T18:45:41.000+0000] {etl_process.py:311} INFO - X_train_scaled guardado en PostgreSQL en la tabla: X_train_scaled
[2024-08-17T18:45:41.000+0000] {etl_process.py:312} INFO - X_train_scaled en XCOM con key: X_train_scaled
[2024-08-17T18:45:41.069+0000] {taskinstance.py:2698} ERROR - Task failed with exception
Traceback (most recent call last):
  File "/home/airflow/.local/lib/python3.8/site-packages/airflow/models/taskinstance.py", line 433, in _execute_task
    result = execute_callable(context=context, **execute_callable_kwargs)
  File "/home/airflow/.local/lib/python3.8/site-packages/airflow/operators/python.py", line 199, in execute
    return_value = self.execute_callable()
  File "/home/airflow/.local/lib/python3.8/site-packages/airflow/operators/python.py", line 216, in execute_callable
    return self.python_callable(*self.op_args, **self.op_kwargs)
  File "/opt/airflow/dags/etl_process.py", line 314, in scale_data
    X_train_scaled.to_sql('X_train_scaled', engine, if_exists='replace', index=False)
NameError: name 'engine' is not defined
[2024-08-17T18:45:41.077+0000] {taskinstance.py:1138} INFO - Marking task as UP_FOR_RETRY. dag_id=etl, task_id=scale_data, execution_date=20240817T184010, start_date=20240817T184540, end_date=20240817T184541
[2024-08-17T18:45:41.083+0000] {standard_task_runner.py:107} ERROR - Failed to execute job 91 for task scale_data (name 'engine' is not defined; 3914)
[2024-08-17T18:45:41.114+0000] {local_task_job_runner.py:234} INFO - Task exited with return code 1
[2024-08-17T18:45:41.124+0000] {taskinstance.py:3280} INFO - 0 downstream tasks scheduled from follow-on schedule check
