[2024-08-21T04:00:33.756+0000] {taskinstance.py:1956} INFO - Dependencies all met for dep_context=non-requeueable deps ti=<TaskInstance: etl2.get_data manual__2024-08-21T04:00:26.016379+00:00 [queued]>
[2024-08-21T04:00:33.773+0000] {taskinstance.py:1956} INFO - Dependencies all met for dep_context=requeueable deps ti=<TaskInstance: etl2.get_data manual__2024-08-21T04:00:26.016379+00:00 [queued]>
[2024-08-21T04:00:33.777+0000] {taskinstance.py:2170} INFO - Starting attempt 1 of 2
[2024-08-21T04:00:33.802+0000] {taskinstance.py:2191} INFO - Executing <Task(PythonOperator): get_data> on 2024-08-21 04:00:26.016379+00:00
[2024-08-21T04:00:33.810+0000] {standard_task_runner.py:60} INFO - Started process 286 to run task
[2024-08-21T04:00:33.815+0000] {standard_task_runner.py:87} INFO - Running: ['***', 'tasks', 'run', 'etl2', 'get_data', 'manual__2024-08-21T04:00:26.016379+00:00', '--job-id', '2', '--raw', '--subdir', 'DAGS_FOLDER/etl_process_2.py', '--cfg-path', '/tmp/tmp2kl4yt79']
[2024-08-21T04:00:33.818+0000] {standard_task_runner.py:88} INFO - Job 2: Subtask get_data
[2024-08-21T04:00:33.901+0000] {task_command.py:423} INFO - Running <TaskInstance: etl2.get_data manual__2024-08-21T04:00:26.016379+00:00 [running]> on host 3578cb081144
[2024-08-21T04:00:34.072+0000] {taskinstance.py:2480} INFO - Exporting env vars: AIRFLOW_CTX_DAG_OWNER='***' AIRFLOW_CTX_DAG_ID='etl2' AIRFLOW_CTX_TASK_ID='get_data' AIRFLOW_CTX_EXECUTION_DATE='2024-08-21T04:00:26.016379+00:00' AIRFLOW_CTX_TRY_NUMBER='1' AIRFLOW_CTX_DAG_RUN_ID='manual__2024-08-21T04:00:26.016379+00:00'
[2024-08-21T04:00:34.844+0000] {taskinstance.py:2698} ERROR - Task failed with exception
Traceback (most recent call last):
  File "/home/airflow/.local/lib/python3.8/site-packages/airflow/models/taskinstance.py", line 433, in _execute_task
    result = execute_callable(context=context, **execute_callable_kwargs)
  File "/home/airflow/.local/lib/python3.8/site-packages/airflow/operators/python.py", line 199, in execute
    return_value = self.execute_callable()
  File "/home/airflow/.local/lib/python3.8/site-packages/airflow/operators/python.py", line 216, in execute_callable
    return self.python_callable(*self.op_args, **self.op_kwargs)
  File "/opt/airflow/dags/etl_process_2.py", line 57, in get_data
    response = s3_client.get_object(Bucket=bucket_name, Key=file_key)
  File "/home/airflow/.local/lib/python3.8/site-packages/botocore/client.py", line 569, in _api_call
    return self._make_api_call(operation_name, kwargs)
  File "/home/airflow/.local/lib/python3.8/site-packages/botocore/client.py", line 1023, in _make_api_call
    raise error_class(parsed_response, operation_name)
botocore.errorfactory.NoSuchKey: An error occurred (NoSuchKey) when calling the GetObject operation: The specified key does not exist.
[2024-08-21T04:00:34.868+0000] {taskinstance.py:1138} INFO - Marking task as UP_FOR_RETRY. dag_id=etl2, task_id=get_data, execution_date=20240821T040026, start_date=20240821T040033, end_date=20240821T040034
[2024-08-21T04:00:34.889+0000] {standard_task_runner.py:107} ERROR - Failed to execute job 2 for task get_data (An error occurred (NoSuchKey) when calling the GetObject operation: The specified key does not exist.; 286)
[2024-08-21T04:00:34.951+0000] {local_task_job_runner.py:234} INFO - Task exited with return code 1
[2024-08-21T04:00:35.179+0000] {taskinstance.py:3280} INFO - 0 downstream tasks scheduled from follow-on schedule check
