[2024-08-17T18:27:08.555+0000] {taskinstance.py:1956} INFO - Dependencies all met for dep_context=non-requeueable deps ti=<TaskInstance: etl.split_data manual__2024-08-17T18:21:49.872219+00:00 [queued]>
[2024-08-17T18:27:08.560+0000] {taskinstance.py:1956} INFO - Dependencies all met for dep_context=requeueable deps ti=<TaskInstance: etl.split_data manual__2024-08-17T18:21:49.872219+00:00 [queued]>
[2024-08-17T18:27:08.561+0000] {taskinstance.py:2170} INFO - Starting attempt 1 of 2
[2024-08-17T18:27:08.569+0000] {taskinstance.py:2191} INFO - Executing <Task(PythonOperator): split_data> on 2024-08-17 18:21:49.872219+00:00
[2024-08-17T18:27:08.573+0000] {standard_task_runner.py:60} INFO - Started process 1777 to run task
[2024-08-17T18:27:08.575+0000] {standard_task_runner.py:87} INFO - Running: ['***', 'tasks', 'run', 'etl', 'split_data', 'manual__2024-08-17T18:21:49.872219+00:00', '--job-id', '58', '--raw', '--subdir', 'DAGS_FOLDER/etl_process.py', '--cfg-path', '/tmp/tmpftu7arc8']
[2024-08-17T18:27:08.577+0000] {standard_task_runner.py:88} INFO - Job 58: Subtask split_data
[2024-08-17T18:27:08.608+0000] {task_command.py:423} INFO - Running <TaskInstance: etl.split_data manual__2024-08-17T18:21:49.872219+00:00 [running]> on host 5a9976bc6527
[2024-08-17T18:27:08.659+0000] {taskinstance.py:2480} INFO - Exporting env vars: AIRFLOW_CTX_DAG_OWNER='***' AIRFLOW_CTX_DAG_ID='etl' AIRFLOW_CTX_TASK_ID='split_data' AIRFLOW_CTX_EXECUTION_DATE='2024-08-17T18:21:49.872219+00:00' AIRFLOW_CTX_TRY_NUMBER='1' AIRFLOW_CTX_DAG_RUN_ID='manual__2024-08-17T18:21:49.872219+00:00'
[2024-08-17T18:27:08.720+0000] {taskinstance.py:2698} ERROR - Task failed with exception
Traceback (most recent call last):
  File "/home/airflow/.local/lib/python3.8/site-packages/airflow/models/taskinstance.py", line 433, in _execute_task
    result = execute_callable(context=context, **execute_callable_kwargs)
  File "/home/airflow/.local/lib/python3.8/site-packages/airflow/operators/python.py", line 199, in execute
    return_value = self.execute_callable()
  File "/home/airflow/.local/lib/python3.8/site-packages/airflow/operators/python.py", line 216, in execute_callable
    return self.python_callable(*self.op_args, **self.op_kwargs)
  File "/opt/airflow/dags/etl_process.py", line 251, in split_data
    X = df_xgb.drop(columns=['operation_amount'])
NameError: name 'df_xgb' is not defined
[2024-08-17T18:27:08.728+0000] {taskinstance.py:1138} INFO - Marking task as UP_FOR_RETRY. dag_id=etl, task_id=split_data, execution_date=20240817T182149, start_date=20240817T182708, end_date=20240817T182708
[2024-08-17T18:27:08.736+0000] {standard_task_runner.py:107} ERROR - Failed to execute job 58 for task split_data (name 'df_xgb' is not defined; 1777)
[2024-08-17T18:27:08.748+0000] {local_task_job_runner.py:234} INFO - Task exited with return code 1
[2024-08-17T18:27:08.762+0000] {taskinstance.py:3280} INFO - 0 downstream tasks scheduled from follow-on schedule check
