[2024-08-17T18:28:54.260+0000] {taskinstance.py:1956} INFO - Dependencies all met for dep_context=non-requeueable deps ti=<TaskInstance: etl.scale_data manual__2024-08-17T18:18:30.738684+00:00 [queued]>
[2024-08-17T18:28:54.265+0000] {taskinstance.py:1956} INFO - Dependencies all met for dep_context=requeueable deps ti=<TaskInstance: etl.scale_data manual__2024-08-17T18:18:30.738684+00:00 [queued]>
[2024-08-17T18:28:54.266+0000] {taskinstance.py:2170} INFO - Starting attempt 1 of 2
[2024-08-17T18:28:54.274+0000] {taskinstance.py:2191} INFO - Executing <Task(PythonOperator): scale_data> on 2024-08-17 18:18:30.738684+00:00
[2024-08-17T18:28:54.278+0000] {standard_task_runner.py:60} INFO - Started process 1989 to run task
[2024-08-17T18:28:54.280+0000] {standard_task_runner.py:87} INFO - Running: ['***', 'tasks', 'run', 'etl', 'scale_data', 'manual__2024-08-17T18:18:30.738684+00:00', '--job-id', '63', '--raw', '--subdir', 'DAGS_FOLDER/etl_process.py', '--cfg-path', '/tmp/tmp0ej3xd3m']
[2024-08-17T18:28:54.281+0000] {standard_task_runner.py:88} INFO - Job 63: Subtask scale_data
[2024-08-17T18:28:54.311+0000] {task_command.py:423} INFO - Running <TaskInstance: etl.scale_data manual__2024-08-17T18:18:30.738684+00:00 [running]> on host 5a9976bc6527
[2024-08-17T18:28:54.362+0000] {taskinstance.py:2480} INFO - Exporting env vars: AIRFLOW_CTX_DAG_OWNER='***' AIRFLOW_CTX_DAG_ID='etl' AIRFLOW_CTX_TASK_ID='scale_data' AIRFLOW_CTX_EXECUTION_DATE='2024-08-17T18:18:30.738684+00:00' AIRFLOW_CTX_TRY_NUMBER='1' AIRFLOW_CTX_DAG_RUN_ID='manual__2024-08-17T18:18:30.738684+00:00'
[2024-08-17T18:28:54.435+0000] {taskinstance.py:2698} ERROR - Task failed with exception
Traceback (most recent call last):
  File "/home/airflow/.local/lib/python3.8/site-packages/airflow/models/taskinstance.py", line 433, in _execute_task
    result = execute_callable(context=context, **execute_callable_kwargs)
  File "/home/airflow/.local/lib/python3.8/site-packages/airflow/operators/python.py", line 199, in execute
    return_value = self.execute_callable()
  File "/home/airflow/.local/lib/python3.8/site-packages/airflow/operators/python.py", line 216, in execute_callable
    return self.python_callable(*self.op_args, **self.op_kwargs)
  File "/opt/airflow/dags/etl_process.py", line 294, in scale_data
    y_train = pd.DataFrame(y_train)
  File "/home/airflow/.local/lib/python3.8/site-packages/pandas/core/frame.py", line 709, in __init__
    mgr = dict_to_mgr(data, index, columns, dtype=dtype, copy=copy, typ=manager)
  File "/home/airflow/.local/lib/python3.8/site-packages/pandas/core/internals/construction.py", line 481, in dict_to_mgr
    return arrays_to_mgr(arrays, columns, index, dtype=dtype, typ=typ, consolidate=copy)
  File "/home/airflow/.local/lib/python3.8/site-packages/pandas/core/internals/construction.py", line 115, in arrays_to_mgr
    index = _extract_index(arrays)
  File "/home/airflow/.local/lib/python3.8/site-packages/pandas/core/internals/construction.py", line 645, in _extract_index
    raise ValueError("If using all scalar values, you must pass an index")
ValueError: If using all scalar values, you must pass an index
[2024-08-17T18:28:54.445+0000] {taskinstance.py:1138} INFO - Marking task as UP_FOR_RETRY. dag_id=etl, task_id=scale_data, execution_date=20240817T181830, start_date=20240817T182854, end_date=20240817T182854
[2024-08-17T18:28:54.452+0000] {standard_task_runner.py:107} ERROR - Failed to execute job 63 for task scale_data (If using all scalar values, you must pass an index; 1989)
[2024-08-17T18:28:54.493+0000] {local_task_job_runner.py:234} INFO - Task exited with return code 1
[2024-08-17T18:28:54.506+0000] {taskinstance.py:3280} INFO - 0 downstream tasks scheduled from follow-on schedule check
