[2024-08-18T16:20:39.185+0000] {taskinstance.py:1956} INFO - Dependencies all met for dep_context=non-requeueable deps ti=<TaskInstance: etl.split_data manual__2024-08-18T16:19:53.151560+00:00 [queued]>
[2024-08-18T16:20:39.190+0000] {taskinstance.py:1956} INFO - Dependencies all met for dep_context=requeueable deps ti=<TaskInstance: etl.split_data manual__2024-08-18T16:19:53.151560+00:00 [queued]>
[2024-08-18T16:20:39.190+0000] {taskinstance.py:2170} INFO - Starting attempt 2 of 3
[2024-08-18T16:20:39.198+0000] {taskinstance.py:2191} INFO - Executing <Task(PythonOperator): split_data> on 2024-08-18 16:19:53.151560+00:00
[2024-08-18T16:20:39.203+0000] {standard_task_runner.py:60} INFO - Started process 16592 to run task
[2024-08-18T16:20:39.205+0000] {standard_task_runner.py:87} INFO - Running: ['***', 'tasks', 'run', 'etl', 'split_data', 'manual__2024-08-18T16:19:53.151560+00:00', '--job-id', '117', '--raw', '--subdir', 'DAGS_FOLDER/etl_process.py', '--cfg-path', '/tmp/tmpox8umj4l']
[2024-08-18T16:20:39.206+0000] {standard_task_runner.py:88} INFO - Job 117: Subtask split_data
[2024-08-18T16:20:39.237+0000] {task_command.py:423} INFO - Running <TaskInstance: etl.split_data manual__2024-08-18T16:19:53.151560+00:00 [running]> on host f0f27744fe62
[2024-08-18T16:20:39.288+0000] {taskinstance.py:2480} INFO - Exporting env vars: AIRFLOW_CTX_DAG_OWNER='***' AIRFLOW_CTX_DAG_ID='etl' AIRFLOW_CTX_TASK_ID='split_data' AIRFLOW_CTX_EXECUTION_DATE='2024-08-18T16:19:53.151560+00:00' AIRFLOW_CTX_TRY_NUMBER='2' AIRFLOW_CTX_DAG_RUN_ID='manual__2024-08-18T16:19:53.151560+00:00'
[2024-08-18T16:20:39.298+0000] {taskinstance.py:2698} ERROR - Task failed with exception
Traceback (most recent call last):
  File "/home/airflow/.local/lib/python3.8/site-packages/airflow/models/taskinstance.py", line 433, in _execute_task
    result = execute_callable(context=context, **execute_callable_kwargs)
  File "/home/airflow/.local/lib/python3.8/site-packages/airflow/operators/python.py", line 199, in execute
    return_value = self.execute_callable()
  File "/home/airflow/.local/lib/python3.8/site-packages/airflow/operators/python.py", line 216, in execute_callable
    return self.python_callable(*self.op_args, **self.op_kwargs)
  File "/opt/airflow/dags/etl_process.py", line 252, in split_data
    X = df.drop(columns=['operation_amount'])
  File "/home/airflow/.local/lib/python3.8/site-packages/pandas/core/frame.py", line 5258, in drop
    return super().drop(
  File "/home/airflow/.local/lib/python3.8/site-packages/pandas/core/generic.py", line 4549, in drop
    obj = obj._drop_axis(labels, axis, level=level, errors=errors)
  File "/home/airflow/.local/lib/python3.8/site-packages/pandas/core/generic.py", line 4591, in _drop_axis
    new_axis = axis.drop(labels, errors=errors)
  File "/home/airflow/.local/lib/python3.8/site-packages/pandas/core/indexes/base.py", line 6699, in drop
    raise KeyError(f"{list(labels[mask])} not found in axis")
KeyError: "['operation_amount'] not found in axis"
[2024-08-18T16:20:39.308+0000] {taskinstance.py:1138} INFO - Marking task as UP_FOR_RETRY. dag_id=etl, task_id=split_data, execution_date=20240818T161953, start_date=20240818T162039, end_date=20240818T162039
[2024-08-18T16:20:39.315+0000] {standard_task_runner.py:107} ERROR - Failed to execute job 117 for task split_data ("['operation_amount'] not found in axis"; 16592)
[2024-08-18T16:20:39.338+0000] {local_task_job_runner.py:234} INFO - Task exited with return code 1
[2024-08-18T16:20:39.351+0000] {taskinstance.py:3280} INFO - 0 downstream tasks scheduled from follow-on schedule check
