[2024-08-21T00:38:26.715+0000] {taskinstance.py:1956} INFO - Dependencies all met for dep_context=non-requeueable deps ti=<TaskInstance: etl2.get_dummies manual__2024-08-21T00:37:39.794651+00:00 [queued]>
[2024-08-21T00:38:26.728+0000] {taskinstance.py:1956} INFO - Dependencies all met for dep_context=requeueable deps ti=<TaskInstance: etl2.get_dummies manual__2024-08-21T00:37:39.794651+00:00 [queued]>
[2024-08-21T00:38:26.729+0000] {taskinstance.py:2170} INFO - Starting attempt 1 of 2
[2024-08-21T00:38:26.748+0000] {taskinstance.py:2191} INFO - Executing <Task(PythonOperator): get_dummies> on 2024-08-21 00:37:39.794651+00:00
[2024-08-21T00:38:26.755+0000] {standard_task_runner.py:60} INFO - Started process 291 to run task
[2024-08-21T00:38:26.761+0000] {standard_task_runner.py:87} INFO - Running: ['***', 'tasks', 'run', 'etl2', 'get_dummies', 'manual__2024-08-21T00:37:39.794651+00:00', '--job-id', '15', '--raw', '--subdir', 'DAGS_FOLDER/etl_process_2.py', '--cfg-path', '/tmp/tmpodrp3f7j']
[2024-08-21T00:38:26.764+0000] {standard_task_runner.py:88} INFO - Job 15: Subtask get_dummies
[2024-08-21T00:38:26.837+0000] {task_command.py:423} INFO - Running <TaskInstance: etl2.get_dummies manual__2024-08-21T00:37:39.794651+00:00 [running]> on host b7fe98c8fee4
[2024-08-21T00:38:26.990+0000] {taskinstance.py:2480} INFO - Exporting env vars: AIRFLOW_CTX_DAG_OWNER='***' AIRFLOW_CTX_DAG_ID='etl2' AIRFLOW_CTX_TASK_ID='get_dummies' AIRFLOW_CTX_EXECUTION_DATE='2024-08-21T00:37:39.794651+00:00' AIRFLOW_CTX_TRY_NUMBER='1' AIRFLOW_CTX_DAG_RUN_ID='manual__2024-08-21T00:37:39.794651+00:00'
[2024-08-21T00:38:27.078+0000] {etl_process_2.py:202} INFO - 
        Para "city" (barrios)" y "building_layout," generaremos variables dummy. 
    
[2024-08-21T00:38:27.112+0000] {taskinstance.py:2698} ERROR - Task failed with exception
Traceback (most recent call last):
  File "/home/airflow/.local/lib/python3.8/site-packages/airflow/models/taskinstance.py", line 433, in _execute_task
    result = execute_callable(context=context, **execute_callable_kwargs)
  File "/home/airflow/.local/lib/python3.8/site-packages/airflow/operators/python.py", line 199, in execute
    return_value = self.execute_callable()
  File "/home/airflow/.local/lib/python3.8/site-packages/airflow/operators/python.py", line 216, in execute_callable
    return self.python_callable(*self.op_args, **self.op_kwargs)
  File "/opt/airflow/dags/etl_process_2.py", line 212, in get_dummies
    df_proc = pd.concat([df_numerico, pd.DataFrame(encoded_array, columns=encoder.get_feature_names_out(['building_layout','city']))], axis=1)
  File "/home/airflow/.local/lib/python3.8/site-packages/sklearn/preprocessing/_encoders.py", line 1211, in get_feature_names_out
    input_features = _check_feature_names_in(self, input_features)
  File "/home/airflow/.local/lib/python3.8/site-packages/sklearn/utils/validation.py", line 2071, in _check_feature_names_in
    raise ValueError("input_features is not equal to feature_names_in_")
ValueError: input_features is not equal to feature_names_in_
[2024-08-21T00:38:27.135+0000] {taskinstance.py:1138} INFO - Marking task as UP_FOR_RETRY. dag_id=etl2, task_id=get_dummies, execution_date=20240821T003739, start_date=20240821T003826, end_date=20240821T003827
[2024-08-21T00:38:27.151+0000] {standard_task_runner.py:107} ERROR - Failed to execute job 15 for task get_dummies (input_features is not equal to feature_names_in_; 291)
[2024-08-21T00:38:27.175+0000] {local_task_job_runner.py:234} INFO - Task exited with return code 1
[2024-08-21T00:38:27.223+0000] {taskinstance.py:3280} INFO - 0 downstream tasks scheduled from follow-on schedule check
