[2024-08-17T18:26:26.911+0000] {taskinstance.py:1956} INFO - Dependencies all met for dep_context=non-requeueable deps ti=<TaskInstance: etl.split_data manual__2024-08-17T18:26:08.636904+00:00 [queued]>
[2024-08-17T18:26:26.916+0000] {taskinstance.py:1956} INFO - Dependencies all met for dep_context=requeueable deps ti=<TaskInstance: etl.split_data manual__2024-08-17T18:26:08.636904+00:00 [queued]>
[2024-08-17T18:26:26.917+0000] {taskinstance.py:2170} INFO - Starting attempt 1 of 2
[2024-08-17T18:26:26.924+0000] {taskinstance.py:2191} INFO - Executing <Task(PythonOperator): split_data> on 2024-08-17 18:26:08.636904+00:00
[2024-08-17T18:26:26.929+0000] {standard_task_runner.py:60} INFO - Started process 1612 to run task
[2024-08-17T18:26:26.931+0000] {standard_task_runner.py:87} INFO - Running: ['***', 'tasks', 'run', 'etl', 'split_data', 'manual__2024-08-17T18:26:08.636904+00:00', '--job-id', '54', '--raw', '--subdir', 'DAGS_FOLDER/etl_process.py', '--cfg-path', '/tmp/tmpuktmd56u']
[2024-08-17T18:26:26.933+0000] {standard_task_runner.py:88} INFO - Job 54: Subtask split_data
[2024-08-17T18:26:26.962+0000] {task_command.py:423} INFO - Running <TaskInstance: etl.split_data manual__2024-08-17T18:26:08.636904+00:00 [running]> on host 5a9976bc6527
[2024-08-17T18:26:27.012+0000] {taskinstance.py:2480} INFO - Exporting env vars: AIRFLOW_CTX_DAG_OWNER='***' AIRFLOW_CTX_DAG_ID='etl' AIRFLOW_CTX_TASK_ID='split_data' AIRFLOW_CTX_EXECUTION_DATE='2024-08-17T18:26:08.636904+00:00' AIRFLOW_CTX_TRY_NUMBER='1' AIRFLOW_CTX_DAG_RUN_ID='manual__2024-08-17T18:26:08.636904+00:00'
[2024-08-17T18:26:27.071+0000] {taskinstance.py:2698} ERROR - Task failed with exception
Traceback (most recent call last):
  File "/home/airflow/.local/lib/python3.8/site-packages/airflow/models/taskinstance.py", line 433, in _execute_task
    result = execute_callable(context=context, **execute_callable_kwargs)
  File "/home/airflow/.local/lib/python3.8/site-packages/airflow/operators/python.py", line 199, in execute
    return_value = self.execute_callable()
  File "/home/airflow/.local/lib/python3.8/site-packages/airflow/operators/python.py", line 216, in execute_callable
    return self.python_callable(*self.op_args, **self.op_kwargs)
  File "/opt/airflow/dags/etl_process.py", line 251, in split_data
    X = df_xgb.drop(columns=['operation_amount'])
NameError: name 'df_xgb' is not defined
[2024-08-17T18:26:27.078+0000] {taskinstance.py:1138} INFO - Marking task as UP_FOR_RETRY. dag_id=etl, task_id=split_data, execution_date=20240817T182608, start_date=20240817T182626, end_date=20240817T182627
[2024-08-17T18:26:27.084+0000] {standard_task_runner.py:107} ERROR - Failed to execute job 54 for task split_data (name 'df_xgb' is not defined; 1612)
[2024-08-17T18:26:27.105+0000] {local_task_job_runner.py:234} INFO - Task exited with return code 1
[2024-08-17T18:26:27.120+0000] {taskinstance.py:3280} INFO - 0 downstream tasks scheduled from follow-on schedule check
