[2024-08-17T18:48:48.909+0000] {taskinstance.py:1956} INFO - Dependencies all met for dep_context=non-requeueable deps ti=<TaskInstance: etl.scale_data manual__2024-08-17T18:48:30.401087+00:00 [queued]>
[2024-08-17T18:48:48.914+0000] {taskinstance.py:1956} INFO - Dependencies all met for dep_context=requeueable deps ti=<TaskInstance: etl.scale_data manual__2024-08-17T18:48:30.401087+00:00 [queued]>
[2024-08-17T18:48:48.914+0000] {taskinstance.py:2170} INFO - Starting attempt 1 of 2
[2024-08-17T18:48:48.922+0000] {taskinstance.py:2191} INFO - Executing <Task(PythonOperator): scale_data> on 2024-08-17 18:48:30.401087+00:00
[2024-08-17T18:48:48.927+0000] {standard_task_runner.py:60} INFO - Started process 4346 to run task
[2024-08-17T18:48:48.929+0000] {standard_task_runner.py:87} INFO - Running: ['***', 'tasks', 'run', 'etl', 'scale_data', 'manual__2024-08-17T18:48:30.401087+00:00', '--job-id', '99', '--raw', '--subdir', 'DAGS_FOLDER/etl_process.py', '--cfg-path', '/tmp/tmpqt58cyod']
[2024-08-17T18:48:48.930+0000] {standard_task_runner.py:88} INFO - Job 99: Subtask scale_data
[2024-08-17T18:48:48.959+0000] {task_command.py:423} INFO - Running <TaskInstance: etl.scale_data manual__2024-08-17T18:48:30.401087+00:00 [running]> on host 5a9976bc6527
[2024-08-17T18:48:49.010+0000] {taskinstance.py:2480} INFO - Exporting env vars: AIRFLOW_CTX_DAG_OWNER='***' AIRFLOW_CTX_DAG_ID='etl' AIRFLOW_CTX_TASK_ID='scale_data' AIRFLOW_CTX_EXECUTION_DATE='2024-08-17T18:48:30.401087+00:00' AIRFLOW_CTX_TRY_NUMBER='1' AIRFLOW_CTX_DAG_RUN_ID='manual__2024-08-17T18:48:30.401087+00:00'
[2024-08-17T18:48:49.012+0000] {etl_process.py:285} INFO - Leyendo Datos
[2024-08-17T18:48:49.020+0000] {etl_process.py:292} INFO - Datos Leidos
[2024-08-17T18:48:49.025+0000] {logging_mixin.py:188} WARNING - /home/***/.local/lib/python3.8/site-packages/sklearn/utils/extmath.py:1050 RuntimeWarning: invalid value encountered in divide
[2024-08-17T18:48:49.026+0000] {logging_mixin.py:188} WARNING - /home/***/.local/lib/python3.8/site-packages/sklearn/utils/extmath.py:1055 RuntimeWarning: invalid value encountered in divide
[2024-08-17T18:48:49.027+0000] {logging_mixin.py:188} WARNING - /home/***/.local/lib/python3.8/site-packages/sklearn/utils/extmath.py:1075 RuntimeWarning: invalid value encountered in divide
[2024-08-17T18:48:49.030+0000] {etl_process.py:314} INFO - X_train_scaled guardado en PostgreSQL en la tabla: X_train_scaled
[2024-08-17T18:48:49.030+0000] {etl_process.py:315} INFO - X_train_scaled en XCOM con key: X_train_scaled
[2024-08-17T18:48:49.243+0000] {etl_process.py:319} INFO - X_test_scaled guardado en PostgreSQL en la tabla: X_test_scaled
[2024-08-17T18:48:49.243+0000] {etl_process.py:320} INFO - X_test_scaled en XCOM con key: X_test_scaled
[2024-08-17T18:48:49.306+0000] {etl_process.py:324} INFO - y_train_scaled guardado en PostgreSQL en la tabla: y_train_scaled
[2024-08-17T18:48:49.306+0000] {etl_process.py:325} INFO - y_train_scaled en XCOM con key: y_train_scaled
[2024-08-17T18:48:49.334+0000] {etl_process.py:329} INFO - y_test_scaled guardado en PostgreSQL en la tabla: y_test_scaled
[2024-08-17T18:48:49.334+0000] {etl_process.py:330} INFO - y_test_scaled en XCOM con key: y_test_scaled
[2024-08-17T18:48:49.389+0000] {python.py:201} INFO - Done. Returned value was: None
[2024-08-17T18:48:49.396+0000] {taskinstance.py:1138} INFO - Marking task as SUCCESS. dag_id=etl, task_id=scale_data, execution_date=20240817T184830, start_date=20240817T184848, end_date=20240817T184849
[2024-08-17T18:48:49.422+0000] {local_task_job_runner.py:234} INFO - Task exited with return code 0
[2024-08-17T18:48:49.433+0000] {taskinstance.py:3280} INFO - 0 downstream tasks scheduled from follow-on schedule check
